<?xml version="1.0" ?>
<!-- =================================================================================== -->
<!-- |    This document was autogenerated by xacro from urdf/my_mobile_robot.xacro     | -->
<!-- |    EDITING THIS FILE BY HAND IS NOT RECOMMENDED                                 | -->
<!-- =================================================================================== -->
<robot name="my_mobile_robot">
  <!--basefootprint-->
  <link name="base_footprint"/>
  <!--basefootprint and baselink joint-->
  <joint name="base_joint" type="fixed">
    <origin xyz="0 0 0.126"/>
    <parent link="base_footprint"/>
    <child link="base_link"/>
  </joint>
  <!--baselink-->
  <link name="base_link">
    <!--visuarise-->
    <visual>
      <geometry>
        <box size="0.3 0.3 0.23"/>
      </geometry>
      <material name="white">
        <color rgba="1.0 1.0 1.0 1.0"/>
      </material>
    </visual>
    <!--collisionattribute-->
    <collision>
      <geometry>
        <box size="0.3 0.3 0.23"/>
      </geometry>
    </collision>
    <!--inertialattribute-->
    <inertial>
      <mass value="1.0"/>
      <inertia ixx="0.01191" ixy="0" ixz="0" iyy="0.01191" iyz="0" izz="0.01500"/>
    </inertial>
  </link>
  <link name="left_wheel">
    <!--visualize-->
    <visual>
      <geometry>
        <cylinder length="0.05" radius="0.035"/>
      </geometry>
      <material name="gray"/>
    </visual>
    <!--collisionattribute-->
    <collision>
      <geometry>
        <cylinder length="0.05" radius="0.035"/>
      </geometry>
    </collision>
    <!--inertialattribute-->
    <inertial>
      <mass value="0.1"/>
      <inertia ixx="5.1458e-5" ixy="0" ixz="0" iyy="5.1458e-5" iyz="0" izz="6.125e-5"/>
    </inertial>
  </link>
  <!--baselink and leftwheel joint-->
  <joint name="left_wheel_joint" type="continuous">
    <axis xyz="0 0 1"/>
    <parent link="base_link"/>
    <child link="left_wheel"/>
    <origin rpy="-1.5708 0 0" xyz="0.0 0.125 -.09"/>
  </joint>
  <link name="right_wheel">
    <!--visualize-->
    <visual>
      <geometry>
        <cylinder length="0.05" radius="0.035"/>
      </geometry>
      <material name="gray"/>
    </visual>
    <!--collisionattribute-->
    <collision>
      <geometry>
        <cylinder length="0.05" radius="0.035"/>
      </geometry>
    </collision>
    <!--inertialattribute-->
    <inertial>
      <mass value="0.1"/>
      <inertia ixx="5.1458e-5" ixy="0" ixz="0" iyy="5.1458e-5" iyz="0" izz="6.125e-5"/>
    </inertial>
  </link>
  <!--baselink and rightwheel joint-->
  <joint name="right_wheel_joint" type="continuous">
    <axis xyz="0 0 1"/>
    <parent link="base_link"/>
    <child link="right_wheel"/>
    <origin rpy="-1.5708 0 0" xyz="0.0 -0.125 -.09"/>
  </joint>
  <!--baselink and basescan joint-->
  <joint name="scan_joint" type="fixed">
    <axis xyz="0 1 0"/>
    <origin rpy="0 0 0" xyz="0 0 0.2"/>
    <parent link="base_link"/>
    <child link="base_scan"/>
  </joint>
  <!--basescan-->
  <link name="base_scan">
    <!--visuarise-->
    <visual>
      <origin rpy="0 0 0" xyz="0 0 0"/>
      <geometry>
        <box size="0.1 0.1 0.1"/>
      </geometry>
      <material name="red">
        <color rgba="1 0 0 1"/>
      </material>
    </visual>
    <!--collisionattribute-->
    <collision>
      <origin rpy="0 0 0" xyz="0 0 0"/>
      <geometry>
        <box size="0.1 0.1 0.1"/>
      </geometry>
    </collision>
    <!--inertialattribute-->
    <inertial>
      <mass value="0.1"/>
      <origin rpy="0 0 0" xyz="0 0 0"/>
      <inertia ixx="0.00017" ixy="0" ixz="0" iyy="0.00017" iyz="0" izz="0.00017"/>
    </inertial>
  </link>
</robot>

