<?xml version="1.0"?>
<robot name="robot_arm">

 <!--world-->
 <link name="world" />

 <!--world and baselink connect joint-->
 <joint name="fixed" type="fixed">
  <parent link="world" />
  <child link="base_link" />
  <child link="base_link1" />
 </joint>

 <!--baselink-->
 <link name="base_link">
  <!--visualize-->
  <visual>
   <geometry>
    <box size="0.4 0.4 0.1" />
   </geometry>
   <color rgba="0.011 0.172 0.074 1.0" />
   <origin rpy="0 0 0" xyz="0 0 0.05" />
  </visual>
  <!--collisionattribute-->
  <collision>
   <geometry>
    <box size="0.4 0.4 0.1" />
   </geometry>
   <origin rpy="0 0 0" xyz="0 0 0.05" />
  </collision>
  <!--inertialattribute-->
  <inertial>
   <mass value="1.0" />
   <origin rpy="0 0 0" xyz="0 0 0.05" />
   <inertia ixx="0.00354" iyy="0.00354" izz="0.00667" ixy="0" ixz="0" iyz="0" />
  </inertial>
 </link>
<!--baselink and torso connect joint-->
 <joint name="hip" type="revolute">
  <parent link="base_link" />
  <child link="torso" />
  <origin rpy="0 0 0" xyz="0.0 0.0 0.1" />
  <axis xyz="0 1 0" />
  <limit lower="0.00" upper="0.00" effort="0.5293" velocity="6.159937255" />
 </joint>

 <!--torso-->
 <link name="torso">
  <!--visualize-->
  <visual>
   <geometry>
    <cylinder length="0.2" radius="0.1" />
   </geometry>
    <color rgba="0.011 0.172 0.074 1.0" />
   <origin rpy="0 0 0" xyz="0 0 0.1" />
  </visual>
  <!--collisionattribute-->
  <collision>
   <geometry>
    <cylinder length="0.2" radius="0.1" />
   </geometry>
   <origin rpy="0 0 0" xyz="0 0 0.1" />
  </collision>
  <!--inertialattribute-->
  <inertial>
   <mass value="1.0" />
   <origin rpy="0 0 0" xyz="0 0 0.1" />
   <inertia ixx="0.02146" iyy="0.02146" izz="0.00125" ixy="0" ixz="0" iyz="0" />
  </inertial>
 </link>
 <!--torso and lowerarm connect joint-->
 <joint name="shoulder" type="revolute">
  <parent link="torso" />
  <child link="lower_arm" />
  <origin rpy="0 0 0" xyz="0.0 -0.2 0.1" />
  <axis xyz="0 1 0" />
  <limit lower="-1.00" upper="0.00" effort="0.5293" velocity="6.159937255" />
 </joint>

<!--lowerarm-->
 <link name="lower_arm">
  <!--visualize-->
  <visual>
   <geometry>
    <cylinder length="2.5" radius="0.1" />
   </geometry>
    <color rgba="0.011 0.172 0.074 1.0" />
   <origin rpy="0 0 0" xyz="0 0 1.25" />
  </visual>
  <!--collisionattribute-->
  <collision>
   <geometry>
    <cylinder length="2.5" radius="0.1" />
   </geometry>
   <origin rpy="0 0 0" xyz="0 0 1.25" />
  </collision>
  <!--inertialattribute-->
  <inertial>
   <mass value="1.0" />
   <origin rpy="0 0 0" xyz="0 0 1.25" />
   <inertia ixx="0.01396" iyy="0.01396" izz="0.00125" ixy="0" ixz="0" iyz="0" />
  </inertial>
 </link>
  <!--lowerarm and upperarm connect joint-->
 <joint name="elbow" type="revolute">
  <parent link="lower_arm" />
  <child link="upper_arm" />
  <origin rpy="0 0 0" xyz="0.0 0.2 2.35" />
  <axis xyz="0 1 0" />
  <limit lower="0.00" upper="2.00" effort="0.5293" velocity="6.159937255" />
 </joint>

<!--upperarm-->
 <link name="upper_arm">
  <!--visualize-->
  <visual>
   <geometry>
    <cylinder length="2.5" radius="0.1" />
   </geometry>
    <color rgba="0.011 0.172 0.074 1.0" />
   <origin rpy="0 0 0" xyz="0 0 1.25" />
  </visual>
  <!--collisionattribute-->
  <collision>
   <geometry>
    <cylinder length="2.5" radius="0.1" />
   </geometry>
   <origin rpy="0 0 0" xyz="0 0 1.25" />
  </collision>
  <!--inertialattribute-->
  <inertial>
   <mass value="1.0" />
   <origin rpy="0 0 0" xyz="0 0 1.25" />
   <inertia ixx="0.01396" iyy="0.01396" izz="0.00125" ixy="0" ixz="0" iyz="0" />
  </inertial>
 </link>

 <!--upper_arm and hand connect joint-->
 <joint name="wrist" type="revolute">
  <parent link="upper_arm" />
  <child link="hand" />
  <origin rpy="0 0 0" xyz="0.0 -0.2 2.4" />
  <axis xyz="0 1 0" />
  <limit lower="-1.00" upper="0.00" effort="0.5293" velocity="6.159937255" />
 </joint>
  
 <!--hand-->
 <link name="hand">
  <!--visualize-->
  <visual>
   <geometry>
    <cylinder length="0.2" radius="0.1" />
   </geometry>
    <color rgba="0.011 0.172 0.074 1.0" />
   <origin rpy="0 0 0" xyz="0 0 0.1" />
  </visual>
  <!--collisionattribute-->
  <collision>
   <geometry>
    <cylinder length="0.2" radius="0.1" />
   </geometry>
   <origin rpy="0 0 0" xyz="0 0 0.1" />
  </collision>
  <!--inertialattribute-->
  <inertial>
   <mass value="1.0" />
   <origin rpy="0 0 0" xyz="0 0 0.1" />
   <inertia ixx="0.02146" iyy="0.02146" izz="0.00125" ixy="0" ixz="0" iyz="0" />
  </inertial>
 </link>
 <!--on_hand and hand connect joint-->
 <joint name="on_hand" type="revolute">
  <parent link="hand" />
  <child link="parm" />
  <origin rpy="0 0 0" xyz="0.0 0.0 0.2" />
  <axis xyz="0 1 0" />
  <limit lower="0.00" upper="0.00" effort="0.5293" velocity="6.159937255" />
 </joint>
  
  <!--on_hand-->
 <link name="parm">
  <!--visualize-->
  <visual>
   <geometry>
    <box size="0.4 0.4 0.1" />
   </geometry>
   <color rgba="0.011 0.172 0.074 1.0" />
   <origin rpy="0 0 0" xyz="0 0 0.05" />
  </visual>
  <!--collisionattribute-->
  <collision>
   <geometry>
    <box size="0.4 0.4 0.1" />
   </geometry>
   <origin rpy="0 0 0" xyz="0 0 0.05" />
  </collision>
  <!--inertialattribute-->
  <inertial>
   <mass value="1.0" />
   <origin rpy="0 0 0" xyz="0 0 0.05" />
   <inertia ixx="0.00354" iyy="0.00354" izz="0.00667" ixy="0" ixz="0" iyz="0" />
  </inertial>
 </link>
  
  
  <!--arm1-->
 <!--baselink-->
 <link name="base_link1">
  <!--visualize-->
  <visual>
   <geometry>
    <box size="0.4 0.4 0.1" />
   </geometry>
   <color rgba="0.011 0.172 0.074 1.0" />
   <origin rpy="0 0 0" xyz="0 3 0.05" />
  </visual>
  <!--collisionattribute-->
  <collision>
   <geometry>
    <box size="0.4 0.4 0.1" />
   </geometry>
   <origin rpy="0 0 0" xyz="0 3 0.05" />
  </collision>
  <!--inertialattribute-->
  <inertial>
   <mass value="1.0" />
   <origin rpy="0 0 0" xyz="0 3 0.05" />
   <inertia ixx="0.00354" iyy="0.00354" izz="0.00667" ixy="0" ixz="0" iyz="0" />
  </inertial>
 </link>
<!--baselink and torso connect joint-->
 <joint name="hip1" type="revolute">
  <parent link="base_link1" />
  <child link="torso1" />
  <origin rpy="0 0 0" xyz="0.0 0.0 0.1" />
  <axis xyz="0 1 0" />
  <limit lower="0.00" upper="0.00" effort="0.5293" velocity="6.159937255" />
 </joint>

 <!--torso-->
 <link name="torso1">
  <!--visualize-->
  <visual>
   <geometry>
    <cylinder length="0.2" radius="0.1" />
   </geometry>
    <color rgba="0.011 0.172 0.074 1.0" />
   <origin rpy="0 0 0" xyz="0 3 0.1" />
  </visual>
  <!--collisionattribute-->
  <collision>
   <geometry>
    <cylinder length="0.2" radius="0.1" />
   </geometry>
   <origin rpy="0 0 0" xyz="0 3 0.1" />
  </collision>
  <!--inertialattribute-->
  <inertial>
   <mass value="1.0" />
   <origin rpy="0 0 0" xyz="0 3 0.1" />
   <inertia ixx="0.02146" iyy="0.02146" izz="0.00125" ixy="0" ixz="0" iyz="0" />
  </inertial>
 </link>
 <!--torso and lowerarm connect joint-->
 <joint name="shoulder1" type="revolute">
  <parent link="torso1" />
  <child link="lower_arm1" />
  <origin rpy="0 0 0" xyz="0.0 -0.2 0.1" />
  <axis xyz="0 1 0" />
  <limit lower="-1.00" upper="0.00" effort="0.5293" velocity="6.159937255" />
 </joint>

<!--lowerarm-->
 <link name="lower_arm1">
  <!--visualize-->
  <visual>
   <geometry>
    <cylinder length="2.5" radius="0.1" />
   </geometry>
    <color rgba="0.011 0.172 0.074 1.0" />
   <origin rpy="0 0 0" xyz="0 3 1.25" />
  </visual>
  <!--collisionattribute-->
  <collision>
   <geometry>
    <cylinder length="2.5" radius="0.1" />
   </geometry>
   <origin rpy="0 0 0" xyz="0 3 1.25" />
  </collision>
  <!--inertialattribute-->
  <inertial>
   <mass value="1.0" />
   <origin rpy="0 0 0" xyz="0 3 1.25" />
   <inertia ixx="0.01396" iyy="0.01396" izz="0.00125" ixy="0" ixz="0" iyz="0" />
  </inertial>
 </link>

</robot>
